Workbook

Sheet Sprint Plan
A2: Due Date | B2: Responsible | C2: Task | E2: Status
A3: EOD 11/1 | B3: KMT | C3: SJE Record Structure | E3: Done
A4: EOD 11/1 | B4: KMT | C4: IP Record Structure | E4: Done
A5: EOD 11/1 | B5: KMT | C5: SAL Record Structure | E5: Done
A6: EOD 11/1 | B6: KMT | C6: Audit Record Structure | E6: Passed
A7: EOD 11/1 | B7: KMT | C7: Consider COGS Account Usage | E7: Done
A8: EOD 11/1 | B8: KMT | C8: Can we make use of non-matched PO records | E8: Done
A9: EOD 11/4 | B9: Rajan | C9: Import Record Structures | E9: Done
A10: EOD 11/4 | B10: Rajan | C10: Prepare Rev Records with new IP Designations using the Revenue IP SS | E10: Done
A11: EOD 11/7 | B11: Rajan | C11: Add 2 new SAL fields | E11: Done
A12: EOD 11/7 | B12: Rajan | C12: Update COA Structures | E12: Done
A13: EOD 11/7 | B13: Rajan | C13: Import the new reference files | E13: Done
D14: COA | E14: Done
D15: COA_ACCOUNT_TYPE | E15: Done
D16: COA_CLASS_CODE | E16: Done
D17: COA_LEDGER_TYPE | E17: Done
A18: EOD 11/7 | B18: Rajan | C18: Create Rules | E18: Done
C19: a | D19: PO sent, reflects Commitment, | E19: Done
C20: b | D20: Inventory received, payable recognized | E20: Done
C21: c | D21: Invoice received for services, expenses recognized | E21: Done
C22: d | D22: Pay invoices for services (can be combined with event type e) | E22: Done
C23: e | D23: Pay invoices for goods (can be combined with event d) | E23: Done
C24: f | D24: Pay for other invoices | E24: Done
C25: g | D25: Sale goods (inv reduction, expense recognized) | E25: Done
C26: h | D26: Tax Receipts (including sales of goods) | E26: Done
A27: EOD 11/18 | B27: Rajan | C27: Prepare two years of data in PO, Payment and Rev Files
A28: EOD 11/18 | B28: Kip/Rajan | C28: Load 1 year of data to platform | E28: Done
A29: EOD 11/18 | B29: Kip | C29: Verify Statistics about the Data | E29: Done | Q29: i | S29: Year-end
D30: count of vendors with no POs | E30: Done
D31: total amount spent on Vendor w and w/o PO | E31: Done
D32: Count of vendors with some POs, but <> in total payment | E32: Done
D33: Total rev vs. total expense for year | E33: Done
D34: Verify ending balances per Account Type per T Account | E34: Done
D35: (For example no inventory balances at end of year) | E35: Done
A36: EOD 11/19 | B36: Kip | C36: Define Year End Rules | E36: Done
A37: EOD 11/19 | B37: Kip/Rajan | C37: Process two years of data in PO, Payment and Rev Files on the platform
D38: Show comparison Reports for year to year
D39: Using same stats as above
A42: December Sprint
A43: EDO 12/6 | B43: Rajan | C43: Record Video
...

Sheet T Accounts Early
B2: Expense Accounts | K2: Revenue | T2: Files
E3: (Various Detailed Accounts from Object Table) | N3: (Various Detailed Accounts from Source Table)
C4: File | D4: Arrg | L4: File | M4: Arrg | P4: File | Q4: Arrg | T4: 1 | U4: POs Matched and Unmatched with NIGP <900
B5: c | C5: 3 | D5: S | E5: Services received | F5: i | G5: 7 | H5: G | I5: Year End Closeout | K5: i | L5: 7 | M5: G | N5: Year End Closeout | O5: h | P5: 6 | Q5: R | R5: Tax reiiepts, goods sold | T5: 2 | U5: POs with Matched payments with NIGP <900
B6: f | C6: 5 | D6: O | E6: pay other invoices | T6: 3 | U6: Payments with Matched PO with NIGP > 900
B7: g | C7: 4 | D7: E | E7: cost of inv sold | T7: 4 | U7: Payments with Matched PO with NIGP<900
T8: 5 | U8: Payments without Matched PO
B9: Accounts Payable | K9: Cash | T9: 6 | U9: Revenue received
C10: File | D10: Arrg | G10: File | L10: File | M10: Arrg | N10: =CofA!C6 -> 1010001 | P10: File | Q10: Arrg | T10: 7 | U10: New Record | V10: Year End
B11: d | C11: 3 | D11: P | E11: pay services invoices | F11: b | G11: 2 | H11: P | I11: Inv received | K11: h | L11: 6 | M11: G | N11: Tax receipts, goods sold | O11: d | P11: 3 | Q11: G | R11: pay services invoices | T11: 8 | U11: Initial Arrangement Data
B12: e | C12: 4 | D12: P | E12: pay inv. Invoices | F12: c | G12: 3 | H12: S | I12: Services received | O12: e | P12: 4 | Q12: G | R12: pay inv. Invoices | T12: Arrangement
O13: f | P13: 5 | Q13: G | R13: pay other invoices | T13: I | U13: Inventory | V13: Inventory attributes, IP = State of VA, "PO All" (Removed PO dates on SAL, use NIGP as Arrangement ID?)
T14: C | U14: Commit | V14: IP = Vendor, "PO All"
T15: P | U15: PO,Pay | V15: IP = Vendor, "PO With Payment"
B16: Inventory Receivable (Commitment Account) | K16: Commitments Payable (Commitment Account) | T16: S | U16: Services | V16: Inventory = Services, IP = Vendor, "Payment With PO"
C17: File | D17: Arrg | G17: File | L17: File | M17: Arrg | N17: =CofA!C22 -> 2010151 | P17: File | Q17: Arrg | T17: R | U17: Revenue | V17: IP = Rev IP, "Taxes"
B18: a | C18: 1 | D18: I | E18: PO Setn for Inv | O18: a | P18: 1 | Q18: C | R18: PO Setn for Inv | T18: G | U18: Generic | V18: IP=State of VA
F19: b | G19: 2 | H19: I | I19: Inv received | K19: b | L19: 2 | M19: P | N19: Inv received | T19: E | U19: Exp Inv | V19: Inventory attributes, IP = Vendor, "Payment with PO"
T20: O | U20: Exp Other | V20: IP = Vendor, "Payment W/O PO"
B22: Inventory - Finished Goods (Financial Account) | K22: Fund | T22: Entry | U22: Event Code
B23: b | C23: 2 | D23: I | E23: Inv Received | F23: g | G23: 4 | H23: I | I23: cost of inv sold | L23: File | M23: Arrg | N23: 3010001 | P23: File | Q23: Arrg | U23: EV00 | V23: Initialize Arrangement Data
K24: i | L24: 7 | M24: G | N24: Year End Closeout | O24: i | P24: 7 | Q24: G | R24: Year End Closeout | T24: a | U24: EV01 | V24: PO sent, reflects Commitment, Non Fin Transaction, Ledger = CMT
T25: b | U25: EV02 | V25: Inventory received, payable recognized Ledger = FIN
B26: Asset Account (BUDGET) | K26: Expense Account (use Undefined Expense) | T26: c | U26: EV03 | V26: Invoice received for services, expenses recognized, Ledger = FIN
C27: File | D27: Arrg | E27: 1090001 | G27: File | H27: Arrg | L27: File | M27: Arrg | N27: 4000000 | P27: File | Q27: Arrg | T27: d | U27: EV04 | V27: Pay invoices for services (can be combined with event type e, file is only different)
T28: e | V28: Pay invoices for goods (can be combined with event d, only file is different)
T29: g | U29: EV06 | V29: Sale goods (inv reduction, expense recognized)
K30: Fund Account | T30: h | U30: EV07 | V30: Tax Receipts (including sales of goods)
L31: File | M31: Arrg | N31: 3010003 | P31: File | Q31: Arrg | T31: i | U31: EV08 | V31: Year-end

Sheet T Accounts Early 2016
B2: Expense Accounts | K2: Revenue | T2: Files
E3: (Various Detailed Accounts from Object Table) | N3: (Various Detailed Accounts from Source Table)
C4: File | D4: Arrg | L4: File | M4: Arrg | P4: File | Q4: Arrg | T4: 1 | U4: POs Matched and Unmatched with NIGP <9000
B5: c | C5: 3 | D5: S | E5: Services received | F5: i | G5: 7 | H5: G | I5: Year End Closeout | K5: i | L5: 7 | M5: G | N5: Year End Closeout | O5: h | P5: 6 | Q5: R | R5: Tax reiiepts, goods sold | T5: 2 | U5: POs with Matched payments with NIGP <9000
B6: f | C6: 5 | D6: O | E6: pay other invoices | T6: 3 | U6: Payments with Matched PO with NIGP > 9000
B7: g | C7: 4 | D7: E | E7: cost of inv sold | T7: 4 | U7: Payments with Matched PO with NIGP<9000
T8: 5 | U8: Payments without Matched PO
B9: Accounts Payable | K9: Cash | T9: 6 | U9: Revenue received
C10: File | D10: Arrg | G10: File | L10: File | M10: Arrg | N10: =CofA!C6 -> 1010001 | P10: File | Q10: Arrg | T10: 7 | U10: New Record | V10: Year End
B11: d | C11: 3 | D11: P | E11: pay services invoices | F11: b | G11: 2 | H11: P | I11: Inv received | K11: h | L11: 6 | M11: G | N11: Tax receipts, goods sold | O11: d | P11: 3 | Q11: G | R11: pay services invoices | T11: 8 | U11: Initial Arrangement Data
B12: e | C12: 4 | D12: P | E12: pay inv. Invoices | F12: c | G12: 3 | H12: S | I12: Services received | O12: e | P12: 4 | Q12: G | R12: pay inv. Invoices | T12: Arrangement
O13: f | P13: 5 | Q13: G | R13: pay other invoices | T13: I | U13: Inventory | V13: Inventory attributes, IP = State of VA, "PO All" (Removed PO dates on SAL, use NIGP as Arrangement ID?)
T14: C | U14: Commit | V14: IP = Vendor, "PO All"
T15: P | U15: PO,Pay | V15: IP = Vendor, "PO With Payment"
B16: Inventory Receivable (Commitment Account) | K16: Commitments Payable (Commitment Account) | T16: S | U16: Services | V16: Inventory = Services, IP = Vendor, "Payment With PO"
C17: File | D17: Arrg | G17: File | L17: File | M17: Arrg | N17: =CofA!C22 -> 2010151 | P17: File | Q17: Arrg | T17: R | U17: Revenue | V17: IP = Rev IP, "Taxes"
B18: a | C18: 1 | D18: I | E18: PO Setn for Inv | O18: a | P18: 1 | Q18: C | R18: PO Setn for Inv | T18: G | U18: Generic | V18: IP=State of VA
F19: b | G19: 2 | H19: I | I19: Inv received | K19: b | L19: 2 | M19: P | N19: Inv received | T19: E | U19: Exp Inv | V19: Inventory attributes, IP = Vendor, "Payment with PO"
T20: O | U20: Exp Other | V20: IP = Vendor, "Payment W/O PO"
B22: Inventory - Finished Goods (Financial Account) | K22: Fund | T22: Entry | U22: Event Code
B23: b | C23: 2 | D23: I | E23: Inv Received | F23: g | G23: 4 | H23: I | I23: cost of inv sold | L23: File | M23: Arrg | N23: 3010001 | P23: File | Q23: Arrg | U23: EV00 | V23: Initialize Arrangement Data
K24: i | L24: 7 | M24: G | N24: Year End Closeout | O24: i | P24: 7 | Q24: G | R24: Year End Closeout | T24: a | U24: EV01 | V24: PO sent, reflects Commitment, Non Fin Transaction, Ledger = CMT
T25: b | U25: EV02 | V25: Inventory received, payable recognized Ledger = FIN
B26: Asset Account (BUDGET) | K26: Expense Account (use Undefined Expense) | T26: c | U26: EV03 | V26: Invoice received for services, expenses recognized, Ledger = FIN
C27: File | D27: Arrg | E27: 1090001 | G27: File | H27: Arrg | L27: File | M27: Arrg | N27: 4000000 | P27: File | Q27: Arrg | T27: d | U27: EV04 | V27: Pay invoices for services (can be combined with event type e, file is only different)
T28: e | V28: Pay invoices for goods (can be combined with event d, only file is different)
T29: g | U29: EV06 | V29: Sale goods (inv reduction, expense recognized)
K30: Fund Account | T30: h | U30: EV07 | V30: Tax Receipts (including sales of goods)
L31: File | M31: Arrg | N31: 3010003 | P31: File | Q31: Arrg | T31: i | U31: EV08 | V31: Year-end

Sheet T Accounts 2017
B2: Expense Accounts | K2: Revenue | T2: Files
E3: (Various Detailed Accounts from Object Table) | N3: (Various Detailed Accounts from Source Table)
C4: File | D4: Arrg | L4: File | M4: Arrg | P4: File | Q4: Arrg | T4: 1 | U4: All POs
B5: d | C5: 5 | D5: G | E5: Inv/Services Received | F5: i | G5: 7 | H5: G | I5: Year End Closeout | K5: i | L5: 7 | M5: G | N5: Year End Closeout | O5: h | P5: 6 | Q5: R | R5: Tax reiiepts, goods sold | T5: 2
T6: 3
T7: 4
T8: 5 | U8: Payments without Matched PO (All Payments)
B9: Accounts Payable | K9: Cash | T9: 6 | U9: Revenue received
C10: File | D10: Arrg | G10: File | L10: File | M10: Arrg | N10: =CofA!C6 -> 1010001 | P10: File | Q10: Arrg | T10: 7 | U10: New Record | V10: Year End
B11: d | C11: 5 | D11: G | E11: pay all invoices | F11: a | G11: 1 | H11: C | I11: PO sent to Vendor | K11: h | L11: 6 | M11: G | N11: Tax receipts, goods sold | O11: d | P11: 5 | Q11: G | R11: pay all invoices | T11: 8 | U11: Budget file
T12: Arrangement
T13: I
T14: C | U14: Commit | V14: IP = Vendor, "PO All"
T15: P
B16: Inventory Receivable (FIN Account) | K16: Commitments Payable (Commitment Account) | T16: S
C17: File | D17: Arrg | G17: File | L17: File | M17: Arrg | N17: =CofA!C22 -> 2010151 | P17: File | Q17: Arrg | T17: R | U17: Revenue | V17: IP = Rev IP, "Taxes"
B18: a | C18: 1 | D18: C | E18: PO Sent to Vendor | F18: d | G18: 5 | H18: G | I18: inv/services received | T18: G | U18: Generic | V18: IP=State of VA
T19: E
T20: O
B22: Inventory - Finished Goods (Financial Account) | K22: Fund | T22: Entry | U22: Event Code
L23: File | M23: Arrg | N23: 3010001 | P23: File | Q23: Arrg | T23: a | U23: EV01-2017 | V23: PO Sent, and AP commitment recognized; Ledger=FIN
K24: i | L24: 7 | M24: G | N24: Year End Closeout | O24: i | P24: 7 | Q24: G | R24: Year End Closeout | T24: b
T25: c
B26: Asset Account (BUDGET) | K26: Expense Account (use Undefined Expense) | T26: d | U26: EV04-2017 | V26: Pay invoices for everything
C27: File | D27: Arrg | E27: 1090001 | G27: File | H27: Arrg | L27: File | M27: Arrg | N27: 4000000 | P27: File | Q27: Arrg | T27: e
B28: j | C28: 8 | D28: G | E28: Budget (Capital) Amounts | K28: j | L28: 8 | M28: G | N28: Budget (Operating) Amounts | T28: g
T29: h | U29: EV07 | V29: Tax Receipts (including sales of goods)
K30: Fund Account | T30: i | U30: EV08 | V30: Year-end
L31: File | M31: Arrg | N31: 3010003 | P31: File | Q31: Arrg | T31: J | U31: EV09 | V31: Load Budgets. If BUDGET_TYPE = OPERATING, Use Expense Account. Else if BUDGET_TYPE = CAPITAL, Use Asset Account. Else Error
O32: j | P32: 8 | Q32: G | R32: Budget Amounts

Sheet VA Journal Attributes (FPEM)
E2: Not Confirmed | F2: Not Confirmed | G2: Not Confirmed | H2: Not Confirmed
A3: FPEM Enteerd | B3: Field Contents | C3: Field Name | D3: FPEM Field Name | E3: Disk Field Format | F3: Memory Field Format | G3: Field Content | H3: Length | I3: Standard Values Used on Most Records | J3: 2017 Data | K3: Description | L3: Structure | M3: PO Example Field | N3: Payment Example Field
C4: Universal Journal | D4: Universal Journal | K4: Common on All Bus. Process
A5: Yes | B5: Source System ID | C5: ujSourceID | D5: src_cd | E5: String | F5: Text | G5: Constant | H5: 16 | I5: See specific values for different record types | K5: Identifier of system or system compoent that created the journal | L5: Universal Journal
A6: Yes | B6: Instrument/Contract ID | C6: ujInstrumentID | D6: arr_num | E6: String | F6: Long | G6: Xref Key | I6: See specific values for different record types | L6: Universal Journal
A7: Yes | B7: Legal Entity (CO. / Owner) | C7: ujLegalEntityID | D7: org_unit_cd | E7: String | F7: Int | G7: Xref Key | H7: 16 | I7: Agency key | J7: Agency key using reverse lookup | K7: Legal Entity, personal identifier | L7: Universal Journal | M7: AGENCY
A8: Yes | D8: partner_org_unit_cd | E8: String | F8: Long | G8: Xref Key | H8: 15 | I8: Blank, nothing in this data to put here. Same as Partner Org Code | L8: Universal Journal | M8: VENDORID
A9: Yes | B9: Center ID | C9: ujCenterID | D9: cost_center | E9: String | F9: Int | G9: Xref Key | H9: 16 | I9: Fund Key | J9: FUND_NAME | K9: Cost or Profit Center | L9: Universal Journal
A10: Yes | B10: Nominal Account | C10: ujAccountID | D10: acct_num | E10: String | F10: Int | G10: Xref Key | I10: COA value (through Object for payments, or Source for Rev. or ARE Rule specific values for POs) | J10: Object/Source Key using Reverse Lookup | K10: Category of the journal, chart of account value | L10: Universal Journal
A11: Yes | D11: event_id | E11: String | F11: Text | G11: Constant | H11: 16 | I11: Will generated unique Event ID | L11: Universal Journal
A12: Yes | B12: Business Event Code | C12: ujBusEventCD | D12: event_cd | E12: String | F12: Text | G12: Constant | H12: 16 | I12: See specific values for different record types | L12: Universal Journal
A13: Yes | B13: Currency Type Code Source | C13: ujCurrencyTypeCodeSourceID | D13: src_curr_type_cd | E13: String | F13: Text | G13: Constant | H13: 16 | I13: Per platform requirements | L13: Universal Journal
A14: Yes | B14: Curr. Code Source | C14: ujCurrencyCodeSourceID | D14: src_curr_cd | E14: String | F14: Text | G14: Constant | H14: 16 | I14: USD (for first test case) | L14: Universal Journal
A15: Yes | B15: Currency Type Code Target | C15: ujCurrencyTypeCodeTargetID | D15: tgt_curr_type_cd | E15: String | F15: Text | G15: Constant | H15: 16 | I15: Per platform requirements | L15: Universal Journal
A16: Yes | B16: Curr. Code Target | C16: ujCurrencyCodeTargetID | D16: tgt_curr_cd | E16: String | F16: Text | G16: Constant | H16: 16 | I16: USD (for first test case) | L16: Universal Journal
A17: Yes | B17: Acctg. Date | C17: ujAcctDate | D17: acct_dt | E17: String | F17: Date | G17: Derived | I17: First day of quarter per file containing data, or PO Date for PO Data | L17: Universal Journal
A18: Yes | B18: Transaction Amount | C18: ujTransAmount | D18: txn_amt | E18: BigDecimal | F18: Number | G18: Value | I18: Amount | L18: Universal Journal
A19: Yes | B19: Process Date | C19: ujProcessDate | D19: processing_date | E19: String | F19: Date | G19: Input Field | I19: ? | L19: Universal Journal | M19: ORDEREDDATE
A20: Yes | B20: Debit Credit Indicator | C20: ujDebitCreditFlg | D20: db_cr_ind | E20: String | F20: Boolean | G20: Constant | H20: 1 | I20: Filled in by Accounting Rules? | L20: Universal Journal | M20: UNITOFMEASURECODE
A21: Yes | B21: Jrnl Line No | C21: ujJrnlLineID | D21: jrnl_line_id | E21: String | F21: Int | G21: Unique ID | I21: Payment records (Pay and Rev) only result in one journal entry per row (so line number is unimportant). PO data when there are multiple rows per PO Number, should be a sequential number of the PO Row Number for a specific PO | L21: Universal Journal
A22: Yes | B22: Journal / Event Description | C22: ujJrnlDescript | D22: jrnl_line_desc | E22: String | F22: Text | G22: Input Field | H22: 2000 | I22: A simple text value of the source of this data | L22: Universal Journal
A23: Yes | B23: Business Function Code | D23: bus_func_cd | E23: String | F23: Text | G23: Constant | H23: 16 | I23: I think this field may actually be very similar to the Event Code. We might be able to delete this field | K23: Identifier of system or system compoent that created the journal | L23: Universal Journal
A24: Yes | B24: Book-code / Basis | C24: ujBookCodeID | D24: book_cd | E24: String | F24: Text | G24: Constant | H24: 16 | I24: USGAAP (for first test) | L24: Universal Journal
A25: Yes | B25: Involved Party ID | C25: ujIPID | D25: ip_rec_id | E25: String | F25: Long | G25: Xref Key | H25: 15 | I25: See specific values for different record types | L25: Universal Journal | M25: VENDORID
A26: Yes | B26: Commitment ID | C26: ujCommitmentID | D26: ujCommitmentID | E26: String | F26: Long | G26: Xref Key | I26: See specific values for different record types | L26: UJ PO Extension
A27: Yes | B27: Original Process ID | C27: ujProcessID | D27: ujProcessID | E27: String | F27: Text | G27: Constant | H27: 16 | I27: I think this field may actually be very similar to the Event Code. We might be able to delete this field | K27: Identifier of system or system compoent that created the journal | L27: Universal Journal
A28: Yes | B28: Original Document ID | C28: ujOriginalDocID | D28: ujOriginalDocID | E28: String | F28: Text | H28: 50 | I28: PO Number on PO records. The row number of the record + File name, to be able to trace to original input record | L28: Universal Journal | M28: PONUMBER
A29: Yes | B29: Ledger | C29: ujLedgerID | D29: ujLedgerID | E29: String | F29: Text | G29: Constant | H29: 16 | I29: "FIN" for Payment Data (Pay and Rev) "CMT" for Commitment books, for PO data | L29: Universal Journal
A30: Yes | B30: Jrnl Type | C30: ujJrnlType | D30: ujJrnlType | E30: String | F30: Text | G30: Constant | H30: 16 | I30: "ACT" for all these records An Actual Financial Journal | K30: ANA - Analytical Journal, such as an allocation process STS - A Statistical Journal, containing a non-monetary value FRC - A Forecast Journal RCN - Reconciliation Balance used to agree to another ledger ACT - An Actual Financial Journal | L30: Universal Journal
A31: Yes | B31: Affiliate Owner ID | C31: ujAffliateEntityID | D31: ujAffliateEntityID | E31: String | F31: Int | G31: Xref Key | H31: 16 | I31: Blank, nothing in this data to put here. Same as Partner Org Code | K31: Counterparty to transaction | L31: Universal Journal
A32: Yes | B32: Project ID | C32: ujProjectID | D32: ujProjectID | E32: String | F32: Int | G32: Xref Key | H32: 16 | I32: Value from Program field on Payment (Pay and Rev) Data | J32: PROGRAM_NAME | L32: Universal Journal
A33: Yes | B33: Product / Material ID | C33: ujProductID | D33: ujProductID | E33: String | F33: Int | G33: Constant | I33: NIGP Code for PO Data. Blank for Puchase and Rev Data | L33: Universal Journal
A34: Yes | B34: Alternate Account Code | C34: ujAltAccountID | D34: ujAltAccountID | E34: String | F34: Int | G34: Constant | I34: Blank, nothing in this data to put here | L34: Universal Journal
A35: Yes | B35: Fiscal Period | C35: ujFiscalPeriod | D35: ujFiscalPeriod | E35: String | F35: Date | G35: Derived | I35: Let's make this the year of the record. It would typically be a month, but because we only get revenue data yearly, let's just say year on all records | L35: Universal Journal
A36: Yes | B36: Transaction Date | C36: ujTransDate | D36: ujTransDate | E36: String | F36: Date | G36: Input Field | I36: Same as acocunting data for all input records | L36: Universal Journal | M36: ORDEREDDATE
A37: Yes | B37: Movement Flag | C37: ujMovementFlg | D37: ujMovementFlg | E37: String | F37: Boolean | G37: Constant | H37: 1 | I37: Do we use movements on the platform? If we do, we can put a Y here. If not, then a N | K37: Indicates if amount is a movement. If not, it is an accumulation | L37: Universal Journal
A38: Yes | B38: Direct vs. Offset Flag | C38: ujDirVsOffsetFlg | D38: ujDirVsOffsetFlg | E38: String | F38: Boolean | G38: Constant | H38: 1 | I38: For all input records it should be a Y. For all records generated by Accounting Rules (offsets to other accounts) it should be a N | L38: Universal Journal
A39: Yes | B39: Reconciliable Flag | C39: ujReconcileFlg | D39: ujReconcileFlg | E39: String | F39: Boolean | G39: Constant | H39: 1 | I39: N for all this data as we have no balances to test these things against | K39: Indicates if associated balance can be reconciled elsewhere | L39: Universal Journal
A40: Yes | B40: Adjustment Flag | C40: ujAdjustFlg | D40: ujAdjustFlg | E40: String | F40: Boolean | G40: Constant | H40: 1 | I40: N for all input data. Only entries that someone makes by hand and loads to the system should be Y | K40: Indicates if journal is an adjustment as opposed to a automated feed | L40: Universal Journal
A41: Yes | B41: Statistical Amount/Quantity | C41: ujStatisticalAmount | D41: ujStatisticalAmount | E41: BigDecimal | F41: Number | G41: Value | I41: Qunaity for any inventory record. Otherwise blank | L41: Universal Journal | M41: QUANTITYORDERED
...

Sheet CofA
H4: DOCUMENTATION ONLY
B5: LEVEL 5 | C5: COA_NOMIINAL_ACCOUNT | D5: COA_ACCOUNT_TYPE | E5: COA_CLASS_CODE | F5: COA_ACCOUNT_NAME | H5: COA_LEDGER_TYPE
C6: 1010001 | D6: 1 | E6: 110 | F6: CASH | H6: FIN
C7: 1010101 | D7: 1 | E7: 110 | F7: ACCOUNTS RECEIVABLE | H7: FIN
C8: 1020001 | D8: 1 | E8: 120 | F8: INVENTORY – WORK IN PROGRESS | H8: FIN
C9: 1020011 | D9: 1 | E9: 120 | F9: INVENTORY – FINISHED GOODS | H9: FIN
C10: 1020101 | D10: 1 | E10: 120 | F10: INVENTORY RECEIVABLE | H10: CMT
C11: 1030001 | D11: 1 | E11: 130 | F11: PREPAYMENTS | H11: FIN
C12: 1030101 | D12: 1 | E12: 130 | F12: EQUIPMENT – LAB | H12: FIN
C13: 1030201 | D13: 1 | E13: 130 | F13: ACCUMULATED DEPRECIATION – LAB EQUIPMENT | H13: FIN
C14: 1030301 | D14: 1 | E14: 130 | F14: EQUIPMENT – OFFICE | H14: FIN
C15: 1030401 | D15: 1 | E15: 130 | F15: ACCUMULATED DEPRECIATION – OFFICE EQUIPMENT | H15: FIN
C16: 1030501 | D16: 1 | E16: 130 | F16: LEASEHOLD IMPROVEMENTS | H16: FIN
C17: 1030601 | D17: 1 | E17: 130 | F17: ACCUMULATED AMORTIZATION – LEASEHOLD IMPROVEMENTS | H17: FIN
... C27: 3010003 | D27: 3 | E27: 310 | F27: FUND BUDGET | H27: BUDGET-CAPITAL
C28: 4000000 | D28: 4 | E28: 400 | F28: UNDEFINED | H28: FIN, AND BUDGET-OPERATNG
C29: 4001000 | D29: 4 | E29: 401 | F29: TAXES | H29: FIN
C30: 4001001 | D30: 4 | E30: 401 | F30: RAILROAD COMPANIES | H30: FIN
C31: 4001002 | D31: 4 | E31: 401 | F31: RETAIL SALES TIRE TAX | H31: FIN
C32: 4001003 | D32: 4 | E32: 401 | F32: CAR LINE COMPANIES | H32: FIN
C33: 4001005 | D33: 4 | E33: 401 | F33: COMMUNICATIONS SALES AND USE TAX - VA RELAY | H33: FIN
C34: 4001006 | D34: 4 | E34: 401 | F34: LIGHT,HEAT,POWER & WATER COMPANIES | H34: FIN
C35: 4001007 | D35: 4 | E35: 401 | F35: ELECTRIC CONSUMPTION TAX | H35: FIN
C36: 4001008 | D36: 4 | E36: 401 | F36: NATURAL GAS CONSUMPTION TAX | H36: FIN
C37: 4001009 | D37: 4 | E37: 401 | F37: SCC-RAILROAD SPECIAL TAX | H37: FIN
C38: 4001010 | D38: 4 | E38: 401 | F38: VALUATION TAXES ON CERTAIN PUBLIC SERVICE CORP | H38: FIN
C39: 4001011 | D39: 4 | E39: 401 | F39: MOTOR VEHICLE CARRIERS-ROLLING STOCK TAX | H39: FIN
C40: 4001012 | D40: 4 | E40: 401 | F40: COMMUNICATIONS SALES AND USE TAX | H40: FIN
... C2774: 5087LF0 | D2774: 5 | E2774: 587 | F2774: INDIRECT COSTS - LOCAL FUNDS | H2774: FIN
C2775: 6000001 | D2775: 6 | E2775: 610 | F2775: TRANSFERS | H2775: FIN
C2776: 7000000 | D2776: 7 | E2776: 700 | F2776: SUSPENSE | H2776: FIN

Sheet Other Tables
A2: Level 3 | B2: COA_ACCOUNT_TYPE | C2: COA_ACCOUNT_TYPE_DESCRIPTION | E2: ARRANGEMENT_TYPE_CODE | F2: ARRANGEMENT_TYPE_DESCRIPTION
B3: 1 | C3: ASSET | E3: 1 | F3: ASSET
B4: 2 | C4: LIABILITY | E4: 2 | F4: LIABILITY
B5: 3 | C5: FUND BALANCE (EQUITY) | E5: 3 | F5: FUND BALANCE (EQUITY)
B6: 4 | C6: REVENUE | E6: 4 | F6: REVENUE
B7: 5 | C7: EXPENSE | E7: 5 | F7: EXPENSE
B8: 6 | C8: TRANSFER | E8: 6 | F8: TRANSFER
B9: 7 | C9: SUSPENSE | E9: 7 | F9: SUSPENSE
E11: hold on this table….
A12: Level 4 | B12: COA_CLASS_CODE | C12: COA_CLASS_DESCRIPTION | E12: COMMITMENT_TYPE_CODE | F12: COMMITMENT_TYPE_DESCRIPTION
B13: 110 | C13: CURRENT ASSETS | E13: 0 | F13: NO COMMITMENT
B14: 120 | C14: INVENTORY | E14: 110 | F14: PAYMENT WITHOUT PO
B15: 130 | C15: PROPERTY, PLANT & EQUIPMENT | E15: 120 | F15: PO WITHOUT PAYMENT
B16: 140 | C16: OTHER ASSETS | E16: 130 | F16: PAYMENT WITH PO
B17: 190 | C17: BUDGET | E17: 140 | F17: PO WITH PAYMENT
B18: 210 | C18: CURRENT LIABILITIES
B19: 220 | C19: LONG TERM LIABILITIES | E19: LEDGER ID VALUES
B20: 310 | C20: FUND BALANCE | E20: FIN | F20: FINANCIAL ACCOUNTING BOOKS
B21: 400 | C21: UNDEFINED | E21: CMT | F21: COMMITMENT/EXPOSURE BOOKS
B22: 401 | C22: TAXES | E22: BUDGET-OPERATING | F22: BUDGET OPERATING
B23: 402 | C23: RIGHTS AND PRIVILEGES | E23: BUDGET-CAPITAL | F23: BUDGET CAPITAL
B24: 403 | C24: SALES OF PROPERTY AND COMMODITIES
B25: 404 | C25: DONATIONS, RECEIPTS AND TRANSFERS | D25: Level 2 | E25: STATEMENT_TYPE
B26: 405 | C26: ASSESSMENTS AND RECEIPTS FOR SUPPORT FOR SPECIAL SERVICES | E26: 1 | F26: BALANCE SHEET
B27: 406 | C27: INSTITUTIONAL REVENUE | E27: 2 | F27: INCOME STATEMENT
B28: 407 | C28: INTEREST, DIVIDEND AND RENTS
B29: 408 | C29: FINES, FORFEITURES, COURT FEES, CODES, PENALTIES, AND ESCHEATS
B30: 409 | C30: OTHER REVENUE | D30: Level 1 | E30: 1 | F30: TRIAL BALANCE
B31: 410 | C31: FEDERAL GRANTS AND CONTRACTS
B32: 411 | C32: FEDERAL GRANTS AND CONTRACTS
B33: 412 | C33: FEDERAL GRANTS AND CONTRACTS
B34: 414 | C34: FEDERAL GRANTS AND CONTRACTS
B35: 415 | C35: FEDERAL GRANTS AND CONTRACTS
B36: 416 | C36: FEDERAL GRANTS AND CONTRACTS
B37: 417 | C37: FEDERAL GRANTS AND CONTRACTS
B38: 419 | C38: FEDERAL GRANTS AND CONTRACTS
B39: 420 | C39: FEDERAL GRANTS AND CONTRACTS
B40: 421 | C40: FEDERAL GRANTS AND CONTRACTS
B41: 423 | C41: FEDERAL GRANTS AND CONTRACTS
B42: 427 | C42: FEDERAL GRANTS AND CONTRACTS
...

Sheet CoA Structure
B2: The following is a reconstruction of the VA Chart of Account, based upon documents: https://www.doa.virginia.gov/reference/CAPP/CAPP_Topics_Cardinal/60101.pdf), https://www.doa.virginia.gov/reference/CAPP/CAPP_Topics_Cardinal/60106.pdf
B5: Cardinal Account ChartField | C5: Account Type
B6: 1XXXXXX | C6: Asset
B7: 2XXXXXX | C7: Liability
B8: 3XXXXXX | C8: Fund Balance (Equity)
B10: 4XXXXXX | C10: Revenue (Operating)
B11: 5XXXXXX | C11: Expenditure (Operating)
B12: 6XXXXXX | C12: Transfer (Operating)
B13: 7 | C13: Suspense
B15: Revenue Accounts are constructed by using the SOURCE Table
C16: 40 + XXXXX (Source Field Value)
C18: the XXXXX can be broken down into:
C19: XX = Class
C20: X = Sub Class
C21: XX = Detailed Source
B23: Expense Accounts are constructued by using the OBJECT Table
C24: 50 + XXXX + 0

Sheet 2019 Rev Source XREF
A1: 2017_SRC_SOURCE_NAME | B1: ADJ_2003_SRC_SOURCE_NAME | C1: SRC_SOURCE_KEY
A2: 1890 Institutn Capcty Bldg Grt | B2: 1890 INSTITUTION CAPACITY BLDG GRANTS | C2: 1439
A3: 2% Motor Fuel Tax | B3: 2% MOTOR FUEL TAX | C3: 9446
A4: 21St Century Comm Learning Ctr | B4: 2% MOTOR FUEL TAX | C4: 9446
A5: 2nd Chce Act Prsnr Rentry Intv | B5: 2% MOTOR FUEL TAX | C5: 9446
A6: Aband Mine Land Reclamatn Pgm | B6: A CERTIFICATE OF LIMITED PARTNERSHIP | C6: 966
A7: ABC Licenses Application Fees | B7: ABC LICENSES APPLICATION FEES | C7: 522
A8: ABC Liter Tax-Localities Share | B8: ABC LITER TAX-LOCALITIES SHARE | C8: 293
A9: ABC Profits | B9: ABC PROFITS | C9: 794
A10: ABC State Sales And Use Tax | B10: ABC STATE SALES AND USE TAX | C10: 478
A11: ABLEnow-Admin Fee | B11: ABC STATE SALES AND USE TAX | C11: 478
A12: Abstinence Education | B12: ABSTINENCE EDUCATION | C12: 531
A13: ACA Hlth Profess Opport Grants | B13: Aca Hlth Profess Opport Grants | C13: 9575
... A1363: Yorktwn Victry Ctr Adm Receipt | B1363: YORKTOWN VICTORY CENTER ADMISSION RECEIPTS | C1363: 882

Sheet 2019 Exp Object XREF
A1: 2017_EXPENSE_TYPES | B1: ADJ_2003_4-DIGIT OBJECT NAME | C1: OBJ_OBJECT_KEY
A2: Acquisition, Bridges | B2: ACQUISITION, BRIDGES | C2: 197
A3: Acquisition, Buildings | B3: ACQUISITION, BUILDINGS | C3: 198
A4: Acquisition, Property | B4: ACQUISITION, PROPERTY | C4: 439
A5: Acquisition, Rights-Of-Way | B5: ACQUISITION, RIGHTS-OF-WAY | C5: 440
A6: Acquisition, Watrway&Imprvemnt | B6: ACQUISITION, WATERWAYS & IMPROVEMENTS | C6: 441
A7: Admin Costs/Local Programs | B7: ADMINISTRATIVE COSTS/LOCAL PROGRAMS | C7: 221
A8: Administrative Costs | B8: ADMINISTRATIVE COSTS | C8: 426
A9: Agency Indirect Cost Recovery | B9: AGENCY INDIRECT COST RECOVERIES | C9: 236
A10: Agency Service Charges | B10: AGENCY SERVICE CHARGES | C10: 377
A11: Agricultural Supplies | B11: AGRICULTURAL SUPPLIES | C11: 335
A12: Agricultural Vehicular Equip | B12: AGRICULTURAL VEHICULAR EQUIPMENT | C12: 108
A13: Aircraft Equipment | B13: AIRCRAFT EQUIPMENT | C13: 109
... A371: X-Ray & Laboratory Services | B371: X-RAY & LABORATORY SERVICES | C371: 140

Sheet Revenue IPs
A3: CATEGROY | B3: IP Name | C3: IP Address | D3: IP City | E3: IP State | F3: IP Country | G3: IP Postal Code | H3: IP e-mail | I3: IP Vendor ID | J3: IP Unit ID: | K3: IP District ID: | L3: IP Source System ID | P3: 2017 Data
A4: 00 | B4: UNDEFINED | C4: UNKNOWN | D4: UNKNOWN | E4: UNKNOWN | I4: 00 | J4: UNDEFINED | P4: ASSESSMENTS AND RECEIPTS FOR SUPPORT OF SPECIAL SERVICES
A5: 01 | B5: TAXPAYERS | C5: UNKNOWN | D5: UNKNOWN | E5: VA | I5: 01 | J5: TAXES | P5: DONATIONS, RECEIPTS, AND TRANSFERS
A6: 02 | B6: TAXPAYERS FOR RIGHT AND PRIVILEGES | C6: UNKNOWN | D6: UNKNOWN | E6: VA | I6: 02 | J6: RIGHTS AND PRIVILEGES | P6: FEDERAL GRANTS AND CONTRACTS
A7: 03 | B7: VARIOUS BUYERS | C7: UNKNOWN | D7: UNKNOWN | E7: VA | I7: 03 | J7: SALES OF PROPERTY AND COMMODITIES | P7: FINES, FORFEITURES, COURT FEES, COSTS, PENALTIES, AND ESCHEATS
A8: 04 | B8: CONTRIBUTORS | C8: UNKNOWN | D8: UNKNOWN | E8: UNKNOWN | I8: 04 | J8: DONATIONS, RECEIPTS AND TRANSFERS | P8: INSTITUTIONAL REVENUE
A9: 05 | B9: ASSESSORS | C9: UNKNOWN | D9: UNKNOWN | E9: UNKNOWN | I9: 05 | J9: ASSESSMENTS AND RECEIPTS FOR SUPPORT FOR SPECIAL SERVICES | P9: INTEREST, DIVIDENDS, AND RENTS
A10: 06 | B10: INSTITUTIONS | C10: UNKNOWN | D10: UNKNOWN | E10: UNKNOWN | I10: 06 | J10: INSTITUTIONAL REVENUE | P10: OTHER REVENUE
A11: 07 | B11: FINANCIAL SERVICES PARTNER | C11: UNKNOWN | D11: UNKNOWN | E11: UNKNOWN | I11: 07 | J11: INTEREST, DIVIDEND AND RENTS | P11: RIGHTS AND PRIVILEGES
A12: 08 | B12: LITIGANTS | C12: UNKNOWN | D12: UNKNOWN | E12: UNKNOWN | I12: 08 | J12: FINES, FORFEITURES, COURT FEES, CODES, PENALTIES, AND ESCHEATS | P12: SALES OF PROPERTY AND COMMODITIES
A13: 09 | B13: OTHERS REVENUE PARTIES | C13: UNKNOWN | D13: UNKNOWN | E13: UNKNOWN | I13: 09 | J13: OTHER REVENUE | P13: TAXES
A14: 10 | B14: FEDERAL GOVERNMENT | C14: UNKNOWN | D14: WASHINGTON DC | E14: DC | F14: US | I14: 10 | J14: FEDERAL GRANTS AND CONTRACTS | P14: TRANSFER PAYMENTS
A15: 11 | B15: FEDERAL GOVERNMENT | C15: UNKNOWN | D15: WASHINGTON DC | E15: DC | F15: US | I15: 11 | J15: FEDERAL GRANTS AND CONTRACTS
A16: 12 | B16: FEDERAL GOVERNMENT | C16: UNKNOWN | D16: WASHINGTON DC | E16: DC | F16: US | I16: 12 | J16: FEDERAL GRANTS AND CONTRACTS
A17: 14 | B17: FEDERAL GOVERNMENT | C17: UNKNOWN | D17: WASHINGTON DC | E17: DC | F17: US | I17: 14 | J17: FEDERAL GRANTS AND CONTRACTS
A18: 15 | B18: FEDERAL GOVERNMENT | C18: UNKNOWN | D18: WASHINGTON DC | E18: DC | F18: US | I18: 15 | J18: FEDERAL GRANTS AND CONTRACTS
A19: 16 | B19: FEDERAL GOVERNMENT | C19: UNKNOWN | D19: WASHINGTON DC | E19: DC | F19: US | I19: 16 | J19: FEDERAL GRANTS AND CONTRACTS
A20: 17 | B20: FEDERAL GOVERNMENT | C20: UNKNOWN | D20: WASHINGTON DC | E20: DC | F20: US | I20: 17 | J20: FEDERAL GRANTS AND CONTRACTS
A21: 19 | B21: FEDERAL GOVERNMENT | C21: UNKNOWN | D21: WASHINGTON DC | E21: DC | F21: US | I21: 19 | J21: FEDERAL GRANTS AND CONTRACTS
A22: 20 | B22: FEDERAL GOVERNMENT | C22: UNKNOWN | D22: WASHINGTON DC | E22: DC | F22: US | I22: 20 | J22: FEDERAL GRANTS AND CONTRACTS
A23: 21 | B23: FEDERAL GOVERNMENT | C23: UNKNOWN | D23: WASHINGTON DC | E23: DC | F23: US | I23: 21 | J23: FEDERAL GRANTS AND CONTRACTS
A24: 23 | B24: FEDERAL GOVERNMENT | C24: UNKNOWN | D24: WASHINGTON DC | E24: DC | F24: US | I24: 23 | J24: FEDERAL GRANTS AND CONTRACTS
A25: 27 | B25: FEDERAL GOVERNMENT | C25: UNKNOWN | D25: WASHINGTON DC | E25: DC | F25: US | I25: 27 | J25: FEDERAL GRANTS AND CONTRACTS
A26: 30 | B26: FEDERAL GOVERNMENT | C26: UNKNOWN | D26: WASHINGTON DC | E26: DC | F26: US | I26: 30 | J26: FEDERAL GRANTS AND CONTRACTS
... A53: 99 | B53: FEDERAL GOVERNMENT | C53: UNKNOWN | D53: WASHINGTON DC | E53: DC | F53: US | I53: 99 | J53: FEDERAL GRANTS AND CONTRACTS

Sheet New NIGP
B2: NIGP Code
B3: Class Description
B4: 500 | C4: Abrasives
B5: 505 | C5: Abrasive Equipment And Tools
B6: 514 | C6: Abrasives, Coated: Cloth, Fiber, Sandpaper, Etc.
B7: 521 | C7: Abrasives, Sandblasting, Metal
B8: 528 | C8: Abrasives, Sandblasting (Other Than Metal)
B9: 542 | C9: Abrasives, Solid: Wheels, Stones, Etc.
B10: 556 | C10: Abrasives, Tumbling (Wheel)
B11: 563 | C11: Grinding And Polishing Compounds: Carborundum, Diamond, Etc. (For Valve
B12: 570 | C12: Pumice Stone
B13: 575 | C13: Recycled Abrasives Products And Supplies
B14: 584 | C14: Steel Wool, Aluminum Wool, Copper Wool, And Lead Wool
B15: 1000 | C15: Acoustical Tile, Insulating Materials, And Supplies
... B747: 91086 | C747: Siding Installation And Repair Services
B974: 91200 CONSTRUCTION SERVICES, GENERAL (INCL. MAINTENANCE AND REPAIR
B975: SERVICES)
B976: NIGP
B977: Code
B978: Description
B979: 91200 CONSTRUCTION SERVICES, GENERAL (INCL. MAINTENANCE AND
B980: REPAIR SERVICES)
B981: 91216 Boring, Drilling, Testing, and Soundings
B982: 91219 Clearing and Grubbing Services
B983: 91220 Construction, Fire Protection (Includes Fire Escapes)
B984: 91221 Construction, Energy Related (All Types)
B985: 91222 Construction, Equestrian Arena
... B1157: 91584 Video Recording
B1158: 91585
B1159: Telecommunication Relay Services (Text Telephone (TTY); Text-To-Voice;
B1160: Voice Carry Over (VCO); Hearing Carry Over (HCO); Speech-To-Speech
B1161: Relay; Video Relay; Spanish Relay; 7-1-1 Access to TRS
B1162: 91590 Video Media Duplicating and Production Services (Including CD ROMs,
B1163: Tapes, etc.)
B1164: 91593 Voice Mail Services
B1165: 91595 Warning System Services, Citizen
B1166: 91596 Web Page Design, Management and Maintenance Services
B1167: 91597 Wiring Services, Data/Voice
B1168: 91800 CONSULTING SERVICES
B1169: NIGP
...

Sheet NIGP Codes
A1: The official NIGP Commodity Book is copyrighted material to be used for reference purposes only and may not be reproduced without a license from Periscope Holdings, Inc.
A2: Class | B2: Item | C2: Description
A3: =TEXT(5,"000") -> 005 | B3: =TEXT(0,"00") -> 00 | C3: ABRASIVES
A4: =TEXT(5,"000") -> 005 | B4: =TEXT(5,"00") -> 05 | C4: Abrasives Equipment and Tools
A5: =TEXT(5,"000") -> 005 | B5: =TEXT(14,"00") -> 14 | C5: Abrasives, Coated: Cloth, Fiber, Sandpaper, etc.
A6: =TEXT(5,"000") -> 005 | B6: =TEXT(21,"00") -> 21 | C6: Abrasives, Sandblasting, Metal
A7: =TEXT(5,"000") -> 005 | B7: =TEXT(28,"00") -> 28 | C7: Abrasives, Sandblasting, Other than Metal
A8: =TEXT(5,"000") -> 005 | B8: =TEXT(42,"00") -> 42 | C8: Abrasives, Solid: Wheels, Stones, etc.
A9: =TEXT(5,"000") -> 005 | B9: =TEXT(56,"00") -> 56 | C9: Abrasives, Tumbling (Wheel)
A10: =TEXT(5,"000") -> 005 | B10: =TEXT(63,"00") -> 63 | C10: Compounds, Grinding and Polishing: Carborundum, Diamond, etc. (See Class 075 For Valve Grinding Compounds)
A11: =TEXT(5,"000") -> 005 | B11: =TEXT(70,"00") -> 70 | C11: Pumice Stone (Inactive, effective January 1, 2016)
A12: =TEXT(5,"000") -> 005 | B12: =TEXT(75,"00") -> 75 | C12: Recycled Abrasives, Products and Supplies
A13: =TEXT(5,"000") -> 005 | B13: =TEXT(84,"00") -> 84 | C13: Wool, Steel, Aluminum, Copper, and Lead
A14: =TEXT(10,"000") -> 010 | B14: =TEXT(0,"00") -> 00 | C14: ACOUSTICAL TILE, INSULATING MATERIALS, AND SUPPLIES
A15: =TEXT(10,"000") -> 010 | B15: =TEXT(5,"00") -> 05 | C15: Acoustical Tile, All Types, Including Recycled Types
A16: =TEXT(10,"000") -> 010 | B16: =TEXT(8,"00") -> 08 | C16: Acoustical Tile Accessories: Channels, Grids, Mounting Hardware, Rods, Runners, Suspension Brackets, Tees, Wall Angles, and Wires
A17: =TEXT(10,"000") -> 010 | B17: =TEXT(9,"00") -> 09 | C17: Acoustical Tile Insulation
A18: =TEXT(10,"000") -> 010 | B18: =TEXT(11,"00") -> 11 | C18: Adhesives and Cements, Acoustical Tile
A19: =TEXT(10,"000") -> 010 | B19: =TEXT(14,"00") -> 14 | C19: Adhesives and Cements, Insulation
A20: =TEXT(10,"000") -> 010 | B20: =TEXT(17,"00") -> 17 | C20: Insulation, Aluminum Foil
A21: =TEXT(10,"000") -> 010 | B21: =TEXT(30,"00") -> 30 | C21: Hardware, Pipe Insulation: Bands, Clips, and Wires
A22: =TEXT(10,"000") -> 010 | B22: =TEXT(38,"00") -> 38 | C22: Hardware, Duct Insulation: Clips, Pins, etc.
A23: =TEXT(10,"000") -> 010 | B23: =TEXT(41,"00") -> 41 | C23: Insulation: Cork, Blocks, Boards, Sheets, etc.
A24: =TEXT(10,"000") -> 010 | B24: =TEXT(45,"00") -> 45 | C24: Insulation and Finish Systems, Exterior
A25: =TEXT(10,"000") -> 010 | B25: =TEXT(53,"00") -> 53 | C25: Insulation, Fiberglass: Batts, Blankets and Rolls
A26: =TEXT(10,"000") -> 010 | B26: =TEXT(56,"00") -> 56 | C26: Foam Glass: Blocks, Sheets, etc.
A27: =TEXT(10,"000") -> 010 | B27: =TEXT(57,"00") -> 57 | C27: Insulation, Foam-in-Place: Phenolic, Urethane, etc.
A28: =TEXT(10,"000") -> 010 | B28: =TEXT(59,"00") -> 59 | C28: Insulation, Foam Plastics: Blocks, Boards, Sheets, etc.
A29: =TEXT(10,"000") -> 010 | B29: =TEXT(61,"00") -> 61 | C29: Insulation, Reflective, Radiant Barrier
A30: =TEXT(10,"000") -> 010 | B30: =TEXT(62,"00") -> 62 | C30: Insulation, Interior
A31: =TEXT(10,"000") -> 010 | B31: =TEXT(63,"00") -> 63 | C31: Insulation, Blown Type
A32: =TEXT(10,"000") -> 010 | B32: =TEXT(64,"00") -> 64 | C32: Insulation, Loose Fill
A33: =TEXT(10,"000") -> 010 | B33: =TEXT(65,"00") -> 65 | C33: Insulation Jacketing, Canvas, Osnaburg, etc.
A34: =TEXT(10,"000") -> 010 | B34: =TEXT(70,"00") -> 70 | C34: Insulation, Magnesia, Blocks, Sheets, etc.
A35: =TEXT(10,"000") -> 010 | B35: =TEXT(72,"00") -> 72 | C35: Insulation, Mineral Wool: Blankets, Blocks, Boards
A36: =TEXT(10,"000") -> 010 | B36: =TEXT(75,"00") -> 75 | C36: Insulation Paints, Primers, Sealers, etc.
A37: =TEXT(10,"000") -> 010 | B37: =TEXT(76,"00") -> 76 | C37: Insulation, Paper Type Material, Cellulose, etc.
A38: =TEXT(10,"000") -> 010 | B38: =TEXT(78,"00") -> 78 | C38: Insulation, Pipe and Tubing, All Types
A39: =TEXT(10,"000") -> 010 | B39: =TEXT(81,"00") -> 81 | C39: Insulation, Preformed, All Types, Ells, Tees, Valves, etc.
A40: =TEXT(10,"000") -> 010 | B40: =TEXT(83,"00") -> 83 | C40: Recycled Insulation Materials and Supplies, All Types
...

Sheet Pre-processing File Requiements
A1: Proposed Layout for FPEM Input Records
A2: Payment Record
B3: Source Code | C3: Contract ID | D3: Org Code | E3: Event Code | F3: Event ID | G3: Accounting Date | H3: Curr. Code | I3: Tran Amount | J3: Account ID | K3: IP ID | L3: Fund Detail | M3: Object | N3: Sub Prog | O3: Party Name
B4: "PaymentSystem" | C4: if PO Number found for payment, PO Number Otherwise a dumb key | D4: Agency Key | E4: "Payment" | F4: Generated Unique ID for each record in file | G4: Date From File name | H4: "USD" | I4: Amount Field from File | J4: ? | K4: Vendor ID if Vendor Found on PO Data using Vendor name from payment, otherwise new Vendor ID for this Vendor Name | L4: Fund Detail from File | M4: Object From File | N4: Sub Prog from File | O4: Vendor Name from File
A7: PO Record
B9: Contract ID | C9: IP ID | D9: Party Name | E9: Org Code | F9: Event Code | G9: Event ID | H9: Account Date | I9: Source Code | J9: PO Number | K9: Product Description | L9: Quantity | M9: Unit of Measure | N9: Unit Price | O9: Account ID | P9: NIGP Code | Q9: NIGP Descript | R9: Unit of Measure Descript | S9: Vendor Part Num | T9: IP Address | U9: IP City | V9: IP State | W9: IP Country | X9: External IP ID | Y9: IP Postal Code | Z9: Ip Email Address
B10: PO Number from File | C10: Vendor ID Field in file | D10: Vendor Name | E10: Agency Key Code from Agency Name lookup | F10: "PurchaseOrder" | G10: PO Number + a number generated for each line | H10: Order Date | I10: "POSystem" | J10: Value from PO File | K10: Value from PO File | L10: Value from PO File | M10: Value from PO File | N10: Value from PO File | O10: Value from PO File | P10: Value from PO File | Q10: Value from PO File | R10: Value from PO File | S10: Value from PO File | T10: Value from PO File | U10: Value from PO File | V10: Value from PO File | W10: Value from PO File | Y10: Value from PO File | Z10: Value from PO File

Sheet Report Structures
B4: First View
C5: ARRANGEMENT_ TYPE_ CODE | D5: ARRANGEMENT_ TYPE_ DESCRIPTION | E5: COA ACCOUNT | F5: AMOUNT
C6: 4 | D6: REVENUE SOURCE | F6: XXX
C7: 5 | D7: EXPENSE SOURCE | F7: XXX
C8: 6 | D8: PO SOURCE | F8: XXX
B10: Drill Down View 1
C11: ARRANGEMENT_ TYPE_ CODE | D11: ARRANGEMENT_ TYPE_ DESCRIPTION | E11: COMMITMENT_ TYPE_ CODE | F11: COMMITMENT_ TYPE_ DESC | G11: AMOUNT
C12: 4 | D12: REVENUE | E12: 0 | F12: NO COMMITMENT | G12: XXX
C13: 5 | D13: EXPENSE | E13: 110 | F13: WITH PO | G13: XXX
C14: 5 | D14: EXPENSE | E14: 120 | F14: WITHOUT PO | G14: XXX
C15: 6 | D15: PO SOURCE | F15: PO ONLY | G15: XXX
C16: 6 | D16: PO SOURCE | F16: PO WITH PAYMENT | G16: XXX
B17: Drill Down View 2
C18: ARRANGEMENT_ TYPE_ CODE | D18: ARRANGEMENT_ TYPE_ DESCRIPTION | E18: COMMITMENT_ TYPE_ CODE | F18: COMMITMENT_ TYPE_ DESC | I18: AMOUNT
C19: 4 | D19: REVENUE | E19: 0 | F19: NO COMMITMENT | I19: XXX
C20: 5 | D20: EXPENSE | E20: 110 | F20: WITH PO | I20: XXX
C21: 5 | D21: EXPENSE | E21: 120 | F21: WITHOUT PO | I21: XXX

Sheet Univ. Journal
B3: Questions
B4: Sub Instrument ID?
B5: Recursive relationship for instruments?
B6: How much source IDs to add
B7: How many chart elements? Product, customer type, etc.?
B8: Platform processing date?
B9: Stat units, and quantity
B10: Position Hash
B13: Field Contents | C13: Field Name | D13: Field Name | E13: Disk Field Format | F13: Memory Field Format | G13: Field Content | H13: Length | I13: Description | J13: Sample Values | K13: Structure | L13: PO Example Field | M13: Payment Example Field
C14: Universal Journal | D14: Universal Journal | I14: Common on All Bus. Process
B15: Involved Party ID | C15: ujIPID | D15: ujIPID | E15: String | F15: Long | G15: Xref Key | H15: 15 | K15: Universal Journal | L15: VENDORID
B16: Instrument/Contract ID | C16: ujInstrumentID | D16: ujInstrumentID | E16: String | F16: Long | G16: Xref Key | K16: Universal Journal
B17: Instrument/Contract ID SubArrangement | C17: ujInstrumentID | D17: ujInstrumentID | E17: String | F17: Long | G17: Xref Key | K17: Universal Journal
B18: Business Event / Journal ID | C18: ujJrnlID | D18: ujJrnlID | E18: String | F18: Long | G18: Unique ID | I18: Unique identifier for each business event/universal journal | K18: Universal Journal
B19: Jrnl Line No | C19: ujJrnlLineID | D19: ujJrnlLineID | E19: String | F19: Int | G19: Unique ID | K19: Universal Journal
A20: x | B20: Business Event Code | C20: ujBusEventCD | D20: ujBusEventCD | E20: String | F20: Text | G20: Constant | H20: 16 | K20: Universal Journal
A21: x | B21: Source System ID | C21: ujSourceID | D21: ujSourceID | E21: String | F21: Text | G21: Constant | H21: 16 | I21: Identifier of system or system compoent that created the journal | K21: Universal Journal
A22: x | B22: Original Process ID | C22: ujProcessID | D22: ujProcessID | E22: String | F22: Text | G22: Constant | H22: 16 | I22: Identifier of system or system compoent that created the journal | K22: Universal Journal
A23: x | B23: Original Document ID | C23: ujOriginalDocID | D23: ujOriginalDocID | E23: String | F23: Text | H23: 50 | K23: Universal Journal | L23: PONUMBER
A24: x | B24: Journal / Event Description | C24: ujJrnlDescript | D24: ujJrnlDescript | E24: String | F24: Text | G24: Input Field | H24: 2000 | K24: Universal Journal
A25: x | B25: Ledger | C25: ujLedgerID | D25: ujLedgerID | E25: String | F25: Text | G25: Constant | H25: 16 | I25: BUD-OPERATING, BUD-CAPITAL, FIN, CMT | K25: Universal Journal
A26: x | B26: Jrnl Type | C26: ujJrnlType | D26: ujJrnlType | E26: String | F26: Text | G26: Constant | H26: 16 | J26: ANA - Analytical Journal, such as an allocation process STS - A Statistical Journal, containing a non-monetary value FRC - A Forecast Journal RCN - Reconciliation Balance used to agree to another ledger ACT - An Actual Financial Journal | K26: Universal Journal
A27: x | B27: Book-code / Basis | C27: ujBookCodeID | D27: ujBookCodeID | E27: String | F27: Text | G27: Constant | H27: 16 | K27: Universal Journal
A28: x | B28: Legal Entity (CO. / Owner) | C28: ujLegalEntityID | D28: ujLegalEntityID | E28: String | F28: Int | G28: Xref Key | H28: 16 | I28: Legal Entity, personal identifier | K28: Universal Journal | L28: AGENCY
A29: x | B29: Center ID | C29: ujCenterID | D29: ujCenterID | E29: String | F29: Int | G29: Xref Key | H29: 16 | I29: Cost or Profit Center | K29: Universal Journal
A30: x | B30: Affiliate Owner ID | C30: ujAffliateEntityID | D30: ujAffliateEntityID | E30: String | F30: Int | G30: Xref Key | H30: 16 | I30: Counterparty to transaction | K30: Universal Journal
A31: x | B31: Affliate Center ID | C31: ujAffliateCenterID | D31: ujAffliateCenterID | E31: String | F31: Int | G31: Xref Key | H31: 16 | K31: Universal Journal
A32: x | B32: Project ID | C32: ujProjectID | D32: ujProjectID | E32: String | F32: Int | G32: Xref Key | H32: 16 | K32: Universal Journal
A33: x | B33: Product / Material ID | C33: ujProductID | D33: ujProductID | E33: String | F33: Int | G33: Constant | K33: Universal Journal
A34: x | B34: Nominal Account | C34: ujAccountID | D34: ujAccountID | E34: String | F34: Int | G34: Xref Key | I34: Category of the journal, chart of account value | K34: Universal Journal
A35: x | B35: Alternate Account Code | C35: ujAltAccountID | D35: ujAltAccountID | E35: String | F35: Int | G35: Constant | K35: Universal Journal
A36: x | B36: Curr. Code Source | C36: ujCurrencyCodeSourceID | D36: ujCurrencyCodeSourceID | E36: String | F36: Text | G36: Constant | H36: 16 | K36: Universal Journal
A37: x | B37: Currency Type Code Source | C37: ujCurrencyTypeCodeSourceID | D37: ujCurrencyTypeCodeSourceID | E37: String | F37: Text | G37: Constant | H37: 16 | J37: Values include FN Functional, PR Presentation, TX Transaction | K37: Universal Journal
A38: x | B38: Curr. Code Target | C38: ujCurrencyCodeTargetID | D38: ujCurrencyCodeTargetID | E38: String | F38: Text | G38: Constant | H38: 16 | K38: Universal Journal
A39: x | B39: Currency Type Code Target | C39: ujCurrencyTypeCodeTargetID | D39: ujCurrencyTypeCodeTargetID | E39: String | F39: Text | G39: Constant | H39: 16 | J39: Values include FN Functional, PR Presentation, TX Transaction | K39: Universal Journal
A40: x | B40: Fiscal Period | C40: ujFiscalPeriod | D40: ujFiscalPeriod | E40: String | F40: Date | G40: Derived | K40: Universal Journal
A41: x | B41: Acctg. Date | C41: ujAcctDate | D41: ujAcctDate | E41: String | F41: Date | G41: Derived | K41: Universal Journal
A42: x | B42: Transaction Date | C42: ujTransDate | D42: ujTransDate | E42: String | F42: Date | G42: Input Field | K42: Universal Journal | L42: ORDEREDDATE
A43: x | B43: Process Date | C43: ujProcessDate | D43: ujProcessDate | E43: String | F43: Date | G43: Input Field | K43: Universal Journal | L43: ORDEREDDATE
B44: Movement Flag | C44: ujMovementFlg | D44: ujMovementFlg | E44: String | F44: Boolean | G44: Constant | H44: 1 | I44: Indicates if amount is a movement. If not, it is an accumulation | J44: y/n | K44: Universal Journal
...

Sheet VA Data Structures
B1: This sheet has column headings from the files downloaded from the state of VA; it notes data structure changes that need to be made
A3: F03 | B3: Q1 | C3: EXP | F3: AGY_AGENCY_KEY | G3: FNDDTL_FUND_DETAIL_KEY | H3: OBJ_OBJECT_KEY | I3: SPRG_SUB_PROGRAM_KEY | J3: VENDOR_NAME | K3: AMOUNT | N3: Agency crosswalk File
F4: 267 | G4: 1552 | H4: 56 | I4: 2701 | J4: BLACKWELLS BOOK SERVICES | K4: 271.93 | N4: AGY_AGENCY_CODE | O4: AGY_AGENCY_KEY | P4: AGY_AGENCY_NAME
B5: Q2 | D5: txt | F5: AGY_AGENCY_KEY | G5: FNDDTL_FUND_DETAIL_KEY | H5: OBJ_OBJECT_KEY | I5: SPRG_SUB_PROGRAM_KEY | J5: VENDOR_NAME | K5: AMOUNT | N5: X00 | O5: 299 | P5: Private College or University
B6: Q3 | F6: AGY_AGENCY_KEY | G6: FNDDTL_FUND_DETAIL_KEY | H6: OBJ_OBJECT_KEY | I6: SPRG_SUB_PROGRAM_KEY | J6: VENDOR_NAME | K6: AMOUNT | N6: 722 | O6: 300 | P6: Office of Inspector General Mental Health
B7: Q4 | F7: AGY_AGENCY_KEY | G7: FNDDTL_FUND_DETAIL_KEY | H7: OBJ_OBJECT_KEY | I7: SPRG_SUB_PROGRAM_KEY | J7: VENDOR_NAME | K7: AMOUNT | N7: 778 | O7: 301 | P7: Department of Forensic Science
A8: F04 | B8: Q1 | F8: AGY_AGENCY_KEY | G8: FNDDTL_FUND_DETAIL_KEY | H8: OBJ_OBJECT_KEY | I8: SPRG_SUB_PROGRAM_KEY | J8: VENDOR_NAME | K8: AMOUNT
B9: Q2 | F9: AGY_AGENCY_KEY | G9: FNDDTL_FUND_DETAIL_KEY | H9: OBJ_OBJECT_KEY | I9: SPRG_SUB_PROGRAM_KEY | J9: VENDOR_NAME | K9: AMOUNT | N9: Ref Fund Detail
B10: Q3 | F10: AGY_AGENCY_KEY | G10: FNDDTL_FUND_DETAIL_KEY | H10: OBJ_OBJECT_KEY | I10: SPRG_SUB_PROGRAM_KEY | J10: VENDOR_NAME | K10: AMOUNT | N10: FNDDTL_FUND_DETAIL_KEY | O10: FNDDTL_FUND_DETAIL_NAME
B11: Q4 | F11: AGY_AGENCY_KEY | G11: FNDDTL_FUND_DETAIL_KEY | H11: OBJ_OBJECT_KEY | I11: SPRG_SUB_PROGRAM_KEY | J11: VENDOR_NAME | K11: AMOUNT | N11: 5525 | O11: DEBT SERVICE FEDERAL MATCH
N12: 5597 | O12: DEBT SERVICE FEDERAL MATCH
A13: F06 | F13: AGY_AGENCY_KEY | G13: FNDDTL_FUND_DETAIL_KEY | H13: OBJ_OBJECT_KEY | I13: SPRG_SUB_PROGRAM_KEY | J13: VENDOR_NAME | K13: AMOUNT | N13: 5650 | O13: DEBT SERVICE FEDERAL MATCH
A15: F08 | F15: AGY_AGENCY_KEY | G15: FNDDTL_FUND_DETAIL_KEY | H15: OBJ_OBJECT_KEY | I15: SPRG_SUB_PROGRAM_KEY | J15: VENDOR_NAME | K15: AMOUNT | N15: Ref obj key
N16: OBJ_OBJECT_KEY | O16: OBJ_OBJECT_NAME
A17: F09 | F17: AGY_AGENCY_KEY | G17: FNDDTL_FUND_DETAIL_KEY | H17: OBJ_OBJECT_KEY | I17: SPRG_SUB_PROGRAM_KEY | J17: VENDOR_NAME | K17: AMOUNT | N17: 67 | O17: OUTBOUND FREIGHT SERVICES
N18: 93 | O18: ORGANIZATION MEMBERSHIPS
A19: F10 | F19: Missing Exp Data | N19: 130 | O19: DENTAL SERVICES
N20: 150 | O20: FISCAL SERVICES
A21: F11 | F21: AGY_AGENCY_KEY | G21: FNDDTL_FUND_DETAIL_KEY | H21: OBJ_OBJECT_KEY | I21: SPRG_SUB_PROGRAM_KEY | J21: VENDOR_NAME | K21: AMOUNT
N22: Ref sub Program
A23: F12 | F23: AGY_AGENCY_KEY | G23: FNDDTL_FUND_DETAIL_KEY | H23: OBJ_OBJECT_KEY | I23: SPRG_SUB_PROGRAM_KEY | J23: VENDOR_NAME | K23: AMOUNT | L23: VOUCHER_DATE | N23: SPRG_SUB_PROGRAM_KEY | O23: SPRG_SUB_PROGRAM_NAME
N24: 3432 | O24: ADMINISTRATIVE AND SUPPORT SERVICES
A25: F13 | F25: AGY_AGENCY_KEY | G25: FNDDTL_FUND_DETAIL_KEY | H25: OBJ_OBJECT_KEY | I25: SPRG_SUB_PROGRAM_KEY | J25: VENDOR_NAME | K25: AMOUNT | L25: VOUCHER_DATE | N25: 3508 | O25: AIRPORT ASSISTANCE
N26: 3581 | O26: INFORMATION SYSTEMS MANAGEMENT AND DIRECTION
A27: F14 | D27: csv | F27: AGY_AGENCY_KEY | G27: AMOUNT | H27: FNDDTL_FUND_DETAIL_KEY | I27: OBJ_OBJECT_KEY | J27: SPRG_SUB_PROGRAM_KEY | K27: VENDOR_NAME | L27: VOUCHER_DATE | N27: 3595 | O27: ADMINISTRATIVE AND SUPPORT SERVICES
F28: 210 | G28: 61.36 | H28: 1401 | I28: 268 | J28: 4172 | K28: AGENCY TRANSACTION VOUCHER | L28: 41500
A29: F15 | F29: AGY_AGENCY_KEY | G29: AMOUNT | H29: FNDDTL_FUND_DETAIL_KEY | I29: OBJ_OBJECT_KEY | J29: SPRG_SUB_PROGRAM_KEY | K29: VENDOR_NAME | L29: VOUCHER_DATE
F32: More information available at: | H32: Overall COA definition | I32: http://www.doa.virginia.gov/reference/CAPP/CAPP_Topics_Cardinal/60101.pdf
H33: Fund details | I33: http://www.doa.virginia.gov/reference/CAPP/CAPP_Topics_Cardinal/60104.pdf
H34: Program (not one of the above) | I34: http://www.doa.virginia.gov/reference/CAPP/CAPP_Topics_Cardinal/60105.pdf
H35: Higher Level Link page | I35: http://www.doa.virginia.gov/reference/CAPP/CAPP_Summary_Cardinal.shtml
H37: Data downlaoded from | I37: http://datapoint.apa.virginia.gov
H39: Requested data from: | I39: webmaster@apa.virginia.gov
J40: http://www.doa.virginia.gov/reference/CAPP/CAPP_Topics_Cardinal/70210.pdf
J41: - Actuals Ledger Extract GL.288A This interface extracts posted summarized transactions from the actuals ledger in Cardinal.
J42: - COA Extract GL.102A This interface extracts valid chart of account information from each of the ChartField tables in Cardinal that are applicable for use.
J43: - Journal Extract GL.595 This interface extracts posted journal data from the journal tables to help agencies reconcile. Journal data will include journals entered online, sub module journals, spreadsheet journal upload, journal upload, CIPPS payroll journal, FAACS journals, and DOA entered journals.
J45: http://www.cardinalproject.virginia.gov/Cardinal%20Interfaces.shtml

Sheet VA PO Example Data
A2: PONUMBER | B2: AGENCY | C2: ORDEREDDATE | D2: VENDORCOMMODITYDESC | E2: QUANTITYORDERED | F2: PRICE | G2: VENDORID | H2: VENDORNAME | I2: VENDORADDRESS | J2: VENDORCITY | K2: VENDORSTATE | L2: VENDORPOSTALCODE | M2: VENDORLOC_EMAILADDRESS | N2: NIGPCODE | O2: NIGPDESCRIPTION | P2: UOMCode | Q2: UOMDesc | R2: VENDORPARTNUMBER
A3: EP2494035-V2 | B3: Department of Juvenile Justice | C3: 42719 | D3: CORE DEPOSIT | E3: 0 | F3: 18 | G3: 157706706 | H3: POWHATAN AUTO AND TRACTOR PARTS INC | I3: 3350 ANDERSON HWY. | J3: POWHATAN | K3: VA | L3: 23139 | M3: rabarden@aol.com | N3: 2000 | O3: AGRICULTURAL EQUIPMENT, IMPLEMENTS, AND ACCESSORIES (SEE CLASS 022 FOR PARTS) | P3: EA | Q3: each | R3: 7526R
A4: PCO1993812-V2 | B4: Department for Aging and Rehabilitative Services | C4: 42719 | D4: Supplier: PCI, Shipping:Freight By Amt | E4: 0 | F4: 10 | G4: 784338654 | H4: BELTWAY SUPPLY INC | I4: 7411 Alban Station Court Suite A102 | J4: Springfield | K4: VA | L4: 22150 | M4: dave@beltwaysupply.com | N4: 96286 | O4: Transportation of Goods and Other Freight Services | P4: EA | Q4: each | R4: Shipping
A5: PCO1993812-V2 | B5: Department for Aging and Rehabilitative Services | C5: 42719 | D5: 7/8&quot; SPLIT KEY RING 50/PK | E5: 0 | F5: 9.31 | G5: 784338654 | H5: BELTWAY SUPPLY INC | I5: 7411 Alban Station Court Suite A102 | J5: Springfield | K5: VA | L5: 22150 | M5: dave@beltwaysupply.com | N5: 45055 | O5: Locks, Key Blanks, and Locksmith Tools (Including Time Locks) | P5: EA | Q5: each | R5: 789406
A6: PCO2086371-V2 | B6: Virginia Department of Health | C6: 42894 | D6: PRINTER,WIDE FMT,OJ7612EAIO | E6: 0 | F6: 300.44 | G6: 12338837 | H6: ACCESS OFFICE PRODUCTS LLC | I6: 6 W Cary Street | J6: Richmond | K6: VA | L6: 23220 | M6: aj@accessofficeproducts.com | N6: 60557 | O6: Paper Trimmers, Hand, Rotary Type | P6: EA | Q6: each | R6: HEWG1X85A
A7: EP2581398 | B7: Virginia Department of Health | C7: 42894 | D7: Framing AC units, replace air conditioner, replace door | E7: 1 | F7: 2010.75 | G7: 16345130 | H7: HILL TOP CONTRACTORS LLC | I7: PO Box 241 | J7: Troutville | K7: VA | L7: 24175-0241 | M7: john@hilltopcontractors.org | N7: 3105 | O7: Air Conditioners (Cooling and Cooling/Heating Types): Window and Wall Mounted, and Parts and Accessories Not Individually Itemized | P7: EA | Q7: each
A8: EP2581399 | B8: Department of Conservation and Recreation | C8: 42894 | D8: Van Costs, Water Charges, Rental Houses, Grab & Go Food sold for VCLF | E8: 1 | F8: 4683.22 | G8: DB0039520 | H8: VIRGINIA CONSERVATION LEGACY FUND INC | I8: PO Box 87 | J8: Natural Bridge | K8: VA | L8: 24578-0087 | M8: Jennifer.Bell@Kissito.org | N8: 95294 | O8: Transportation Services For the Elderly, Handicapped, Incapacitated, Prisoners, Juries, etc. | P8: EA | Q8: each
A9: A181_170000647 | B9: Department of Labor and Industry | C9: 42894 | D9: SKC PASSIVE SAMPLERS FOR FORMALDEHYDE PACK/10 BUYER WILL CONTACT VENDOR WITH CREDIT CARD FOR PAYMENT OF INVOICE. | E9: 1 | F9: 239.55 | G9: 109909569 | H9: COLONIAL SCIENTIFIC INC | I9: 2015 W. Laburnum Ave | J9: RICHMOND | K9: VA | L9: 23227 | M9: dillon.barnett@colonialscientific.com | N9: 11519 | O9: Culture Media, Prepared (For Microbial Cultures See 495-38) | P9: PK | Q9: pack | R9: UMEX 100
A10: A181_170000648 | B10: Department of Labor and Industry | C10: 42894 | D10: EAR PLUGS, 32DB, CORDLESS, UNIVERSAL, DISPOSABLE, 200 PER PACK BUYER WILL CONTACT VENDOR WITH CREDIT CARD FOR PAYMENT OF INVOICE. | E10: 2 | F10: 26.63 | G10: 109909569 | H10: COLONIAL SCIENTIFIC INC | I10: 2015 W. Laburnum Ave | J10: RICHMOND | K10: VA | L10: 23227 | M10: dillon.barnett@colonialscientific.com | N10: 26952 | O10: Eye, Ear, Nose, and Throat Preparations | P10: BX | Q10: box | R10: 99-G1283-204
A11: A181_170000652 | B11: Department of Labor and Industry | C11: 42894 | D11: HEWLETT PACKARD PRINT CARTRIDGE QUOTE NO. 0000325 BUYER WILL CONTACT THE VENDOR WITH A CHARGE CARD FOR PAYMENT OF INVOICE. | E11: 1 | F11: 307.44 | G11: 79774525 | H11: ABACUS OFFICE SOLUTIONS LLC | I11: PO Box 25024 | J11: Richmond | K11: VA | L11: 23260-5024 | M11: admin@abacusofficesolutions.com | N11: 20772 | O11: Printer Accessories and Supplies: Chemicals, Forms Tractors, Inks and Cartridges, Paper, Label Sheets, Sheet Feeders, Toner Cartridges, Wheels, etc. | P11: EA | Q11: each | R11: HEW-C8543X
A12: A181_170000653 | B12: Department of Labor and Industry | C12: 42894 | D12: DELL TONER CRTDG, LSR - 2150CD, 2155, BK, 3K HIGH YIELD" QUOTE NO. 007214 BUYER WILL CONTACT VENDOR WITH CREDIT CARD FOR PAYMENT OF INVOICE." | E12: 2 | F12: 121.15 | G12: 929720183 | H12: TRI-CITY OFFICE PRODUCTS INC | I12: 2100 Westmoreland St. | J12: Richmond | K12: VA | L12: 23230 | M12: Teresa@tcopi.com | N12: 20772 | O12: Printer Accessories and Supplies: Chemicals, Forms Tractors, Inks and Cartridges, Paper, Label Sheets, Sheet Feeders, Toner Cartridges, Wheels, etc. | P12: EA | Q12: each | R12: DLLN51XP
A13: A181_170000653 | B13: Department of Labor and Industry | C13: 42894 | D13: DELL TONER CRTDG, CYN,2.5K | E13: 2 | F13: 119.98 | G13: 929720183 | H13: TRI-CITY OFFICE PRODUCTS INC | I13: 2100 Westmoreland St. | J13: Richmond | K13: VA | L13: 23230 | M13: Teresa@tcopi.com | N13: 20772 | O13: Printer Accessories and Supplies: Chemicals, Forms Tractors, Inks and Cartridges, Paper, Label Sheets, Sheet Feeders, Toner Cartridges, Wheels, etc. | P13: EA | Q13: each | R13: DLL769T5
A14: A181_170000653 | B14: Department of Labor and Industry | C14: 42894 | D14: DELL TONER CRTDG, LSR, MA, 2.5K | E14: 2 | F14: 119.98 | G14: 929720183 | H14: TRI-CITY OFFICE PRODUCTS INC | I14: 2100 Westmoreland St. | J14: Richmond | K14: VA | L14: 23230 | M14: Teresa@tcopi.com | N14: 20772 | O14: Printer Accessories and Supplies: Chemicals, Forms Tractors, Inks and Cartridges, Paper, Label Sheets, Sheet Feeders, Toner Cartridges, Wheels, etc. | P14: EA | Q14: each | R14: DLL8WNV5
